Workbook
Name Slicer_Gender: #N/A
Name Slicer_Monthly_income: #N/A

Sheet Project_Summary
A1: Fuel Consumption Analysis - Phaltan Survey 2025
A2: Primary Survey | Phaltan, Maharashtra | December 2025
B4: 567 | E4: =Clean_Data_Summary!B27 -> 3336.4427 | H4: =Per_Capita_Expenses!I3 -> 750.05726
B7: Total Respondents | E7: Avg Monthly Fuel(₹) | H7: Avg Per Capita(₹)
A11: Key Results Table
A13: Metric | B13: Value | C13: Interpretation
A14: Pearson Correlation (Income vs Fuel) | B14: =Correlation!K2 -> 0.51836596 | C14: Moderate positive relationship
A15: ANOVA F-statistic (Vehicle Owernship) | B15: =ANOVA1!M33 -> 150.81051 | C15: Highly significant
A16: ANOVA p-value (Vehicle Ownership) | B16: =ANOVA1!N33 -> 9.9800412e-72 | C16: Vehicle ownership drives fuel use
A17: ANOVA F-statistic (Income Groups) | B17: =ANOVA2!M18 -> 41.785378 | C17: Significant across income groups
A18: ANOVA p-value (Income Groups) | B18: =ANOVA2!N18 -> 1.3889177e-36 | C18: Income significantly affects fuel
A19: T-test (Gender difference) | B19: ='T-test'!E2 -> 5.2783151e-30 | C19: Males spend 3x more than females
A20: Multiple Regression Adj.R2 | B20: =Regression1!H6 -> 0.51758499 | C20: 4 variables explain 51.76% variance
A21: Effect Size ῃ2 (Vehicle Ownership) | B21: =ANOVA1!J40 -> 0.44555593 | C21: Large effect
A22: Effect Size ῃ2 (Income Groups) | B22: =ANOVA2!M25 -> 0.27135939 | C22: Moderate -large effect
A23: Male avg fuel expense | B23: ='T-test'!F5 -> 4730.6187 | C23: 4731
A24: Female avg Fuel expense | B24: ='T-test'!F6 -> 1530.2227 | C24: 1530
A26: Sheet Index
A28: Sheet Name | B28: Contents
A29: Form Responses | B29: Raw survey data - 597 original responses
A30: clean_data | B30: Cleaned dataset - 568 rows, 30 columns
A31: Clean_Data_Summary | B31: Column-wise summary of cleaned data ( min, max, mean, median, mode, count)
A32: Outlier_detection | B32: IQR method - 35 high outliers identified
A33: Descriptive_Statistics | B33: Mean, median, SD, min, max, skewness fpr 5 variables
A34: Pie_Chart | B34: Distribution of vehicle types ownership (percentage-wise)
A35: Box_plot | B35: Box plot visualization for detecting outliers and data spread
A36: Pivot_Charts | B36: Interactive Charts summarizing fuel usage across categories
A37: Fuel_Data_Used_Avg_Fuel(l) | B37: Avg fuel consumption (liters) by vehicle type
A38: Avg_Fuel(LMonth) | B38: Pivot table for Avg fuel consumption (liters) by vehicle type
A39: Avg_Fuel_Expense | B39: Avg fuel expenditure analysis
... A53: Dashboard | B53: Interactive dashboard with KPI cards and slicers

Sheet Form Responses 1
A1: Timestamp | B1: 1) Name | C1: 2) Age (eg. 21,22,18,etc) | D1: 3) Gender | E1: 4) Area of residence | F1: 5) occupation | G1: 6) Monthly income | H1: 7) Total family members | I1: 8) No. of vehicles in family | J1: 9) Type of vehicle | K1: 10) Type of fuel required for it. [Bike ] | L1: 10) Type of fuel required for it. [Scooty ] | M1: 10) Type of fuel required for it. [Car ] | N1: 10) Type of fuel required for it. [Commercial ] | O1: 10) Type of fuel required for it. [electric vehicle ] | P1: A] Bike details 11) Age of bike | Q1: 12) Daily distance travelled by bike | R1: 13)Fuel required monthly | S1: B] Scooty details 14)Age of Scooty | T1: 15)Daily distance travelled by Scooty | U1: 16)Fuel required monthly | V1: C] Car details 17)Age of Car | W1: 18)Daily distance travelled by Car | X1: 19)Fuel required monthly | Y1: D. Commercial Vehicle Details 20)Age | Z1: 21)Daily distance travelled | AA1: 22) Fuel required monthly | AB1: E. Electric Vehicle Details 23)Electricity consumption (kWh/month) | AC1: 24)Daily distance travelled | AD1: 25)Age of EV | AE1: 26)Total monthly fuel expense of your household (₹) | AF1: 27)Preferred fuel station brand | AG1: 28) Reason for choosing this brand | AH1: 29)Distance from home to workplace/college (km) | AI1: 30)Main purpose of using your vehicle | AJ1: 31)How often do you use public transport? | AK1: 32) Which type of public transport do you use? | AL1: 33)Would you consider buying an Electric Vehicle (EV)? | AM1: 34)If YES or MAYBE, what is your reason? | AN1: 35)If NO, what is your reason? | AO1: 35. Any suggestions about fuel rates or transportation ?
A2: 45945.517 | B2: Ankita Baburao Gawade | C2: 19 | D2: Female | E2: Rural | F2: Agriculture | G2: 30,000-50,000 | H2: 5 | I2: 1 | J2: bikes | K2: Petrol | P2: 20litre | S2: Indian oil | U2: 10km | X2: 18 | AA2: Work | AD2: 10km | AE2: private | AF2: Petrol | AG2: Cng | AH2: 3 | AI2: Daily | AJ2: Bike | AK2: Good
A3: 45945.518 | B3: Apeksha Sachin Ahiwale | C3: 20 | D3: Female | E3: Urban | F3: Student | G3: 50,000-70,000 | H3: 4 | I3: 2 | J3: bikes, Scooty | K3: Petrol | P3: 500 - 600 rupees | S3: Bharat petroleum | T3: Bharat petroleum | U3: 50km | V3: 20km | X3: 34 | Y3: 25 | AA3: Work | AB3: School / Colleges | AD3: 20km | AF3: Petrol | AG3: No | AH3: 4 | AI3: Often | AJ3: Scooty | AK3: Should be decreased.... the rate must be less so people can easily transport
A4: 45959.476 | B4: Rahul Patil | C4: 27 | D4: Male | E4: Urban | F4: private sector | G4: 50,000-70,000 | H4: 4 | I4: 2 | J4: bikes, Four wheeler | K4: Petrol | P4: 15 L | R4: 45 L | S4: Indian oil | U4: 10 KM | W4: 20 KM | X4: 4 YEAR | Z4: 3 YEAR | AA4: Work | AC4: Travel | AD4: 8 KM | AE4: private | AF4: Petrol | AG4: yes | AH4: 2 | AI4: Rarely | AJ4: Bike | AK4: “Government should reduce petrol tax.”
A5: 45959.485 | B5: Savita Kale | C5: 39 | D5: Female | E5: Rural | F5: Agriculture | G5: 10,000-30,000 | H5: 5 | I5: 1 | J5: bikes | K5: Petrol | P5: 55 | S5: Bharat petroleum | U5: 6 KM | X5: 6 YEARS | AA5: Market and field work | AD5: 5 KM | AE5: private | AF5: petrol | AG5: no | AH5: 1 | AI5: Weekly | AJ5: bike | AK5: petrol rate should be 80rs
A6: 45959.512 | B6: Shivani | C6: 21 | D6: Female | E6: Rural | F6: Student | G6: 50,000-70,000 | H6: 6 | I6: 4 | J6: Scooty | T6: Indian oil | V6: 10 km | X6: 7 years | AB6: School / Colleges | AD6: 3 km | AE6: private | AF6: Scooty | AG6: No | AH6: 5 | AI6: Rarely | AJ6: Scooty | AK6: Concession for women
A7: 45959.518 | B7: Siddhant kumbhar | C7: 20 | D7: Male | E7: Rural | F7: College student | G7: 70,000-1,00,000 | H7: 4 | I7: 2 | J7: bikes, Four wheeler | K7: Petrol | P7: 15 L | R7: 10 L | S7: Indian oil | U7: 9 km | W7: 7 km | X7: 15 years | Z7: 8 years | AA7: School / Colleges | AC7: Travel | AD7: 3 km | AE7: private | AF7: Petrol | AG7: No | AH7: 2 | AI7: Rarely | AJ7: Bike | AK7: Lower the rate of petrol
A8: 45959.523 | B8: Nikita Rajpurohit | C8: 21 | D8: Female | E8: Urban | F8: Student | G8: 70,000-1,00,000 | H8: 5 | I8: 1 | J8: Scooty | T8: Indian oil | V8: 3 km | Y8: 4.5 years | AB8: School / Colleges | AD8: 2 km | AE8: private | AF8: Scooty | AG8: No | AH8: 3 | AI8: Rarely | AJ8: Scooty | AK8: Rates are fine but petrol should be of good quality
A9: 45959.527 | B9: Tejashree Bankar | C9: 21 | D9: Female | E9: Rural | F9: Student | G9: 50,000-70,000 | H9: 6 | I9: 1 | J9: bikes | K9: Petrol | P9: 30 L | S9: Indian oil | U9: 30 km | X9: 13 years | AA9: Work | AD9: 13 km | AE9: private | AF9: Bike | AG9: No | AH9: 3 | AI9: Often | AJ9: Bike | AK9: Rate should be less
A10: 45959.53 | B10: Suhani balip | C10: 21 | D10: Female | E10: Rural | F10: Student | G10: 70,000-1,00,000 | H10: 4 | I10: 3 | J10: Scooty | T10: Indian oil | V10: 30 km | Y10: 2 years | AB10: School / Colleges | AD10: 13 km | AE10: private | AF10: Scooty | AG10: No | AH10: 3 | AI10: Sometimes | AJ10: Scooty | AK10: Should be less
A11: 45959.533 | B11: Ankita Gaikwad | C11: 21 | D11: Female | E11: Rural | F11: Student | G11: 50,000-70,000 | H11: 5 | I11: 1 | J11: bikes | K11: Petrol | P11: 15 L | S11: Indian oil | U11: 10 km | X11: 20 years | AA11: School / Colleges | AD11: 3 km | AE11: private | AF11: Petrol | AG11: Yes | AH11: 2 | AI11: Weekly | AJ11: Bike | AK11: Rate should be minimised
A12: 45974.821 | B12: Subhash Jadhav | C12: 55 | D12: Male | E12: Rural | F12: Government Sector | G12: 30,000-50,000 | H12: 6 | I12: 1 | J12: bikes | K12: Petrol | P12: 15 liter | S12: Indian oil | U12: 40 km | X12: 14 years | AA12: Work | AD12: 10 km | AE12: private | AF12: Petrol | AG12: No | AH12: 1 | AI12: Often | AJ12: Bike
A13: 45976.845 | B13: Dipti sanjay shirtode | C13: 21 | D13: Female | F13: Housewife | H13: 3 | I13: 1 | J13: bikes | K13: Petrol | P13: 5000 | R13: 5000 | S13: Indian oil | T13: Indian oil | U13: 15km | V13: 15 km | W13: 15 km | X13: 5year | Y13: 6year | Z13: 4 years | AA13: Work | AB13: Work | AC13: Work | AD13: 20 km | AE13: private | AF13: Petrol | AG13: Scooty four wheeler | AH13: Yes | AJ13: Bike | AK13: 105 litres for petrol
A14: 45976.848 | B14: Mane anjali sunil | C14: 21 | D14: Female | E14: Urban | F14: Government Sector | G14: above 1,00,000 | H14: 4 | I14: 2 | J14: bikes, Scooty, Four wheeler | K14: CNG | P14: No | R14: 5000litar | S14: HP | T14: Bharat petroleum | U14: 10kimi | V14: 20kimi | W14: २०kimi | X14: 5varsha | Y14: 3varash | Z14: 5varasha | AA14: School / Colleges | AB14: for dropping and picking up children | AC14: Work | AD14: 2kimi | AE14: public transport | AF14: सीएजी | AG14: Yes | AH14: 2 | AI14: Daily | AJ14: Yes | AK14: No
A15: 45976.849 | B15: Amar dhumal | C15: 20 | D15: Male | E15: Mumbai | F15: business | G15: 30,000-50,000 | H15: 6 | I15: 1 | J15: bikes, Four wheeler | K15: Petrol | P15: 45 | R15: 15 | S15: HP | T15: HP | U15: 130 .120km | V15: 60km | W15: 300km | X15: 4 | Y15: 12 | Z15: 8 | AA15: Travel | AC15: Travel | AD15: 1 | AE15: public transport | AF15: 440 | AG15: CNG | AI15: Weekly | AJ15: 19
A16: 45976.851 | B16: Dipti sanjay shirtode | C16: 21 | D16: Female | E16: Urban | F16: Housewife | G16: 10,000-30,000 | H16: 3 | I16: 1 | J16: bikes | K16: Petrol | P16: 5000 | R16: 5000 | S16: Bharat petroleum | T16: Indian oil | U16: 20 km | V16: 10 km | W16: 30 km | X16: 4 years | Y16: 5 years | Z16: 4 years | AA16: Work | AB16: Work | AC16: Work | AD16: 20 to 30km | AE16: private | AF16: Petrol | AG16: Scooty or four wheeler | AJ16: Bike | AK16: 105 litres for petrol
A17: 45976.863 | B17: Shaikh khushiya siraj | C17: 22 | D17: Female | E17: Rural | F17: Housewife | G17: below 10,000 | H17: 4 | I17: 2 | J17: bikes, Scooty | K17: Petrol | P17: 4500 | S17: Indian oil | T17: Indian oil | U17: Daily | X17: 5 | Y17: 6 | AA17: Work | AB17: School / Colleges | AD17: 30 | AE17: private
A18: 45976.87 | B18: Dhembare Dnyaneshwari Nivas | C18: 20 | D18: Female | E18: Rural | G18: 30,000-50,000 | H18: 4 | I18: 1 | J18: bikes | K18: Petrol | S18: Indian oil | U18: 20 | X18: 18 | AA18: for dropping and picking up children | AE18: private | AG18: Electric | AH18: 2 | AI18: Daily | AJ18: No | AK18: 60
A19: 45976.87 | B19: Jagtap Sonu Dattatray | C19: 20 | D19: Female | E19: Rural | F19: Agriculture | G19: 50,000-70,000 | H19: 4 | I19: 3 | J19: bikes, Four wheeler, Tractor | K19: Petrol, diesel, CNG | P19: 10 lit | R19: 200kg | S19: Bharat petroleum | T19: Indian oil | U19: 50km | V19: 20km | W19: 500km | X19: 9 years old | Y19: No | Z19: 3 years | AA19: Work | AB19: No | AC19: Travel | AD19: 100 | AE19: private | AF19: All | AG19: Yes cng | AH19: No | AI19: No | AJ19: No | AK19: No
A20: 45976.877 | B20: Sanidhya sanjay suryavanshi | C20: 19 | D20: Female | E20: Rural | F20: Agriculture | G20: 50,000-70,000 | H20: 5 | I20: 2 | J20: bikes, Scooty | K20: Petrol | S20: Indian oil | T20: Indian oil | U20: 40 km | V20: 30 | Y20: 1 year | AA20: Work | AB20: School / Colleges | AD20: Baramati to someshwar | AE20: private | AF20: Indian fuel | AG20: Yes | AH20: 4 | AI20: Weekly | AJ20: Scooty | AK20: 5
A21: 45976.891 | B21: Sahil Mane | C21: 22 | D21: Male | E21: Urban | F21: private sector | G21: 70,000-1,00,000 | H21: 4 | I21: 3 | J21: bikes, Scooty, Four wheeler | K21: Petrol | P21: 1500 | R21: 5000 | S21: Indian oil | T21: Indian oil | U21: 25 | V21: 15 | W21: 30 | X21: 13 year | Y21: 4 year | Z21: 3 year | AA21: Work | AB21: School / Colleges | AC21: Work | AD21: 500 m | AE21: Nothing | AF21: Petrol | AG21: Yes I can | AH21: 3 | AI21: No use | AJ21: Bike | AK21: 104
A22: 45976.903 | B22: Mulik Aaradhana Shamrao | C22: 19 | D22: Female | E22: Rural | F22: Student | G22: 10,000-30,000 | H22: 4 | I22: 2 | J22: Scooty | K22: Petrol | P22: 10 lit | S22: Indian oil | T22: Indian oil | U22: 20 | V22: 5 | X22: 5 | Y22: 10 | AA22: Work | AB22: Work | AD22: 10 | AE22: private | AF22: Petrol | AG22: इलेक्ट्रिक | AI22: Weekly | AK22: 60 rupees
A23: 45976.904 | B23: Snehal Somnath Kumbhar | C23: 24 | D23: Female | E23: Rural | F23: Housewife | G23: below 10,000 | H23: 3 | I23: 1 | J23: Scooty | K23: Petrol | T23: Bharat petroleum | V23: 25km | Y23: 10 year | AB23: Work | AD23: 10km | AE23: private | AF23: Cng | AG23: Ho | AH23: 1 | AI23: Often | AJ23: Two wheeler | AK23: इंधनाचे दर मापक असावेत
A24: 45976.905 | B24: Dhagare Vrushali Jayram | C24: 26 | D24: Female | E24: Urban | F24: Student | G24: below 10,000 | H24: 3 | I24: 1 | J24: Scooty | T24: Jio | V24: 50km | Y24: 15 | AD24: 5km | AE24: public transport | AF24: - | AG24: Might be in future | AH24: 2 | AI24: Weekly | AJ24: Public transport | AK24: NA
A25: 45976.908 | B25: Samruddhi Mangesh Gaikwad | C25: 20 | D25: Female | E25: Rural | F25: Student | G25: below 10,000 | H25: 5 | I25: 1 | J25: Scooty | T25: Bharat petroleum | V25: 2-4km | Y25: 6years | AB25: Work | AD25: 10km | AE25: private
A26: 45976.909 | B26: Jotiba holam | C26: 50 | D26: Male | E26: Rural | F26: business | G26: 10,000-30,000 | H26: 6 | I26: 2 | J26: bikes, Scooty | K26: Petrol | P26: 8 liter | R26: No four wheeler | S26: Indian oil | T26: Indian oil | U26: 16 km | V26: Not daily | W26: No | X26: 23 | Y26: 7 | Z26: No | AA26: Both work and college | AB26: Travel | AC26: No | AD26: 8 km | AE26: private | AF26: Petrol | AG26: No | AH26: 2 | AI26: Often | AJ26: Bike | AK26: Fuel prices change every day at 6 am, so it is important to check today's rates.
A27: 45977.434 | B27: Rajesh Patil | C27: 26 | D27: Male | E27: Urban | F27: private sector | G27: 30,000-50,000 | H27: 4 | I27: 2 | J27: bikes, Four wheeler | K27: Petrol | P27: 12 L | R27: 30 L | S27: Indian oil | U27: 10 km | W27: 7 km | X27: 4 years | Z27: 6 years | AA27: Work | AC27: for dropping and picking up children | AD27: 4 km | AE27: private | AF27: bike | AG27: Yes, willing to switch to Electric Vehicle (EV) | AH27: 2 | AI27: Occasionally | AJ27: bike | AK27: Fuel rates should be more stable and government should reduce prices to make daily travel affordable for middle-class families
A28: 45977.524 | B28: Akash Patil. | C28: 22 | D28: Male | E28: Rural | F28: private sector | G28: 10,000-30,000 | H28: 4 | I28: 2 | J28: bikes, car | K28: Petrol | M28: Petrol | P28: 4 Years | Q28: 25 km | R28: 18 liters | V28: 3 Years | W28: 30 km | X28: 55liters | AE28: 7000 | AF28: Indian Oil | AG28: Fuel quality | AH28: 12 km | AI28: Office | AJ28: Rarely | AK28: Bus | AL28: Maybe | AM28: Low running cost | AN28: Lack of charging stations | AO28: Fuel prices should be stable and charging stations increased.
A29: 45977.532 | B29: Supriya Jadhav | C29: 28 | D29: Female | E29: Urban | F29: private sector | G29: 10,000-30,000 | H29: 3 | I29: 2 | J29: bikes | K29: Petrol | P29: 6 years | Q29: 15-20km | R29: 17-18 litres | AI29: Office | AJ29: Weekly | AK29: Bus, Auto | AL29: Yes | AM29: Eco-friendly, Rising petrol/diesel prices, New technology | AN29: Lack of charging stations | AO29: Government must maintain the prices of fuel and support to eco friendly vehicles like EV ...and also pay more attention on public transportation it could be much better..
A30: 45977.55 | B30: Ghadge Rutuja. | C30: 24 | D30: Female | E30: Urban | F30: private sector | G30: 50,000-70,000 | H30: 4 | I30: 2 | J30: Scooty, car | L30: Petrol | M30: CNG | Q30: - | S30: 3 years | T30: 20 km | U30: 15 liters | V30: 2 years | W30: 35 km | X30: 35 kg CNG | AE30: 6,500₹ | AF30: Shell | AG30: Fuel quality | AH30: 10 km | AI30: Office | AJ30: Monthly | AK30: Bus | AL30: Yes | AM30: Rising petrol/diesel prices | AN30: Long charging time | AO30: Improve CNG availability.
A31: 45977.555 | B31: Suhani Himmat Mane | C31: 21 | D31: Female | E31: Rural | F31: Student | G31: below 10,000 | H31: 4 | I31: 1 | J31: bikes | K31: Petrol | P31: 10 year | Q31: 11km | R31: 30 litre | AE31: 3000 | AF31: Indian Oil | AG31: Closer to home | AH31: 11km | AI31: College | AJ31: Daily | AK31: Bus | AL31: Yes | AM31: Eco-friendly | AN31: Lack of charging stations, Long charging time | AO31: Rate must be affordable for everyone
A32: 45977.555 | B32: Vijay pawar | C32: 29 | D32: Male | E32: Rural | F32: Agriculture | G32: 10,000-30,000 | H32: 4 | I32: 2 | J32: bikes, Commercial vehicle | K32: Petrol | N32: Diesel | P32: 7years | Q32: 20km | R32: 75L | Y32: 7years | Z32: 50km | AA32: 100L | AE32: 9200 | AF32: Indian Oil | AG32: Price | AH32: 11km | AI32: Agriculture-related | AJ32: Rarely | AK32: Bus | AL32: Yes | AM32: Low running cost, Rising petrol/diesel prices | AN32: Lack of charging stations, Long charging time | AO32: Reduce Disel rates for farmers
A33: 45977.56 | B33: Sakshi Gejage | C33: 20 | D33: Female | E33: Rural | H33: 6 | I33: 1 | J33: Scooty | L33: Petrol | Q33: 12 km | S33: 1 year | T33: 10 km | U33: 10 liter | AF33: Indian Oil | AG33: Fuel quality | AH33: 14 km | AI33: College | AJ33: Daily | AK33: Bus | AL33: No | AM33: Eco-friendly | AN33: Not confident in EV technology | AO33: No
A34: 45977.562 | B34: Rushikesh Balaso Shinde | C34: 20 | D34: Male | E34: Rural | F34: Student | H34: 5 | I34: 1 | J34: bikes | K34: Petrol | P34: 3 | Q34: 30000 | R34: 2000 | AF34: Indian Oil | AG34: Fuel quality, Better service, Trust/Brand image | AH34: 10 | AI34: School pickup/drop | AJ34: Daily | AK34: I don’t use public transport | AL34: Maybe | AM34: Eco-friendly
A35: 45977.562 | B35: Mahesh Shinde 28 | C35: 28 | D35: Male | E35: Rural | F35: Agriculture | G35: 30,000-50,000 | H35: 5 | I35: 3 | J35: bikes, car, Commercial vehicle | K35: Petrol | M35: Diesel | N35: Diesel | P35: 5 yrs. | Q35: 10km | R35: 8 liters | V35: 6 yrs. | W35: 25 km | X35: 45 litres | Y35: 7 yrs. | Z35: 20 km | AA35: 60 litres | AE35: ₹10,000 | AF35: HP | AG35: Better service | AH35: 15 km | AI35: Agriculture-related | AJ35: Rarely | AK35: Private Bus | AL35: No | AN35: Lack of charging stations | AO35: Diesel prices should reduce for farmers.
A36: 45977.563 | B36: Snehal Jadhav | C36: 20 | D36: Female | E36: Urban | F36: College student | G36: below 10,000 | H36: 3 | I36: 1 | J36: Scooty | L36: Petrol | S36: 2 years | T36: 12 km | U36: 10 litres | AE36: 1,200₹ | AF36: BPCL | AG36: Closer to home | AH36: 6 km | AI36: College | AJ36: Weekly | AK36: Shared Rickshaw | AL36: Yes | AM36: Eco-friendly | AO36: Public buses should increase frequency.
A37: 45977.566 | B37: Anuja Aru | C37: 35 | D37: Female | E37: Urban | F37: private sector | G37: 30,000-50,000 | H37: 2 | I37: 2 | J37: bikes, car | K37: Petrol | M37: Diesel | P37: 6 years | Q37: 10kms | R37: 20l | V37: 13years | W37: 45kms | X37: 70l | AE37: 10k | AF37: Shell | AG37: Fuel quality, Better service, Trust/Brand image | AH37: 21kms | AI37: Office | AJ37: Rarely | AK37: Auto | AL37: No | AN37: Lack of charging stations, Not confident in EV technology | AO37: Fuel rates would be less
A38: 45977.567 | B38: Kolekar Prathamesh | C38: 26 | D38: Male | E38: Rural | F38: daily wages | G38: 10,000-30,000 | H38: 6 | I38: 1 | J38: bikes | K38: Petrol | P38: 8 yrs. | Q38: 40 km | R38: 28 litres | AE38: 3,000₹ | AF38: Indian Oil | AG38: Price | AH38: 18 km | AI38: Market/Shopping | AJ38: Weekly | AK38: Bus | AL38: Maybe | AM38: Low running cost | AO38: Reduce petrol prices.
A39: 45977.571 | B39: Neha jadhav | C39: 23 | D39: Female | E39: Urban | F39: private sector | G39: 30,000-50,000 | H39: 3 | I39: 1 | J39: Scooty | L39: Petrol | S39: 3years | T39: 18 km | U39: 12L | AE39: 1500 | AF39: BPCL | AG39: Closer to home | AH39: 7km | AI39: Office | AJ39: Weekly | AK39: Auto | AL39: Maybe | AM39: Eco-friendly | AO39: Increase woman friendly transport options
A40: 45977.572 | B40: Salunkhe Rohit | C40: 32 | D40: Male | E40: Urban | F40: business | G40: above 1,00,000 | H40: 4 | I40: 2 | J40: car, Electric Vehicle | M40: Petrol | O40: Electric | V40: 3 yrs. | W40: 40 km. | X40: 60 liters | AB40: 60 kWh/month | AC40: 25 km | AD40: 1 yrs. | AE40: ₹9,500 | AF40: Reliance | AG40: Trust/Brand image | AH40: 20 km | AI40: Office | AJ40: Never | AK40: I don’t use public transport | AL40: Yes | AM40: New technology | AO40: More EV charging stations needed.
...

Sheet clean_data
A1: Age | B1: Gender | C1: Monthly_income | D1: Total_family _members | E1: Num_vehicles_in_family | F1: Type_vehicle | G1: fuel_required_Bike | H1: fuel_required_Scooty | I1: fuel_required_Car | J1: fuel_required_Commercial | K1: Age_bike | L1: Daily_distance_travelled_bike | M1: fuel_monthly_bikes | N1: Age_Scooty | O1: Daily_distance_travelled_Scooty | P1: Fuel_required_monthly_scooty | Q1: Age_Car | R1: Daily_distance_travelled_Car | S1: Fuel_required_monthly_car | T1: Age_commercial | U1: Daily_distance_travelled_commercial | V1: Fuel_required_monthly_commercial | W1: Total_monthly_fuel_expense | X1: Preferred_fuel_brand | Y1: Distance_home_ workplace | Z1: Main_purpose_vehicle | AA1: How_often_use_PT | AB1: type_PT | AC1: consider_ev | AD1: Is_Outliers
A2: 21 | B2: Female | C2: below 10,000 | D2: 4 | E2: 1 | F2: bikes | G2: Petrol | K2: 10 | L2: 11 | M2: 30 | W2: 3000 | X2: Indian Oil | Y2: 11 | Z2: College | AA2: Daily | AB2: Bus | AC2: Yes | AD2: =IF(OR(Form_Responses34[[#This Row],[Total_monthly_fuel_expense ]]>10040,Form_Responses34[[#This Row],[Total_monthly_fuel_expense ]]<-4760),"Outlier","Normal") -> Normal
A3: 29 | B3: Male | C3: 10,000 - 30,000 | D3: 4 | E3: 2 | F3: bikes, Commercial vehicle | G3: Petrol | J3: Diesel | K3: 7 | L3: 20 | M3: 75 | T3: 7 | U3: 50 | V3: 1 | W3: 9200 | X3: Indian Oil | Y3: 11 | Z3: Agriculture-related | AA3: Rarely | AB3: Bus | AC3: Yes | AD3: =IF(OR(Form_Responses34[[#This Row],[Total_monthly_fuel_expense ]]>10040,Form_Responses34[[#This Row],[Total_monthly_fuel_expense ]]<-4760),"Outlier","Normal") -> Normal
A4: 20 | B4: Female | C4: 10,000 - 30,000 | D4: 6 | E4: 1 | F4: Scooty | H4: Petrol | N4: 1 | O4: 10 | P4: 10 | W4: 1000 | X4: Indian Oil | Y4: 14 | Z4: College | AA4: Daily | AB4: Bus | AC4: No | AD4: =IF(OR(Form_Responses34[[#This Row],[Total_monthly_fuel_expense ]]>10040,Form_Responses34[[#This Row],[Total_monthly_fuel_expense ]]<-4760),"Outlier","Normal") -> Normal
A5: 20 | B5: Male | C5: 10,000 - 30,000 | D5: 5 | E5: 1 | F5: bikes | G5: Petrol | K5: 3 | L5: 30 | M5: 20 | W5: 1000 | X5: Indian Oil | Y5: 10 | Z5: School pickup/drop | AA5: Daily | AB5: I don’t use public transport | AC5: Maybe | AD5: =IF(OR(Form_Responses34[[#This Row],[Total_monthly_fuel_expense ]]>10040,Form_Responses34[[#This Row],[Total_monthly_fuel_expense ]]<-4760),"Outlier","Normal") -> Normal
A6: 28 | B6: Male | C6: 30,000 - 50,000 | D6: 5 | E6: 3 | F6: bikes, car, Commercial vehicle | G6: Petrol | I6: Diesel | J6: Diesel | K6: 5 | L6: 10 | M6: 8 | Q6: 6 | R6: 25 | S6: 45 | T6: 7 | U6: 20 | V6: 60 | W6: 10000 | X6: HP | Y6: 15 | Z6: Agriculture-related | AA6: Rarely | AB6: Private Bus | AC6: No | AD6: =IF(OR(Form_Responses34[[#This Row],[Total_monthly_fuel_expense ]]>10040,Form_Responses34[[#This Row],[Total_monthly_fuel_expense ]]<-4760),"Outlier","Normal") -> Normal
A7: 20 | B7: Female | C7: below 10,000 | D7: 3 | E7: 1 | F7: Scooty | H7: Petrol | N7: 2 | O7: 12 | P7: 10 | W7: 1200 | X7: BPCL | Y7: 6 | Z7: College | AA7: Weekly | AB7: Shared Rickshaw | AC7: Yes | AD7: =IF(OR(Form_Responses34[[#This Row],[Total_monthly_fuel_expense ]]>10040,Form_Responses34[[#This Row],[Total_monthly_fuel_expense ]]<-4760),"Outlier","Normal") -> Normal
A8: 35 | B8: Female | C8: 30,000 - 50,000 | D8: 2 | E8: 2 | F8: bikes, car | G8: Petrol | I8: Diesel | K8: 6 | L8: 10 | M8: 20 | Q8: 13 | R8: 45 | S8: 70 | W8: 1000 | X8: Shell | Y8: 21 | Z8: Office | AA8: Rarely | AB8: Auto | AC8: No | AD8: =IF(OR(Form_Responses34[[#This Row],[Total_monthly_fuel_expense ]]>10040,Form_Responses34[[#This Row],[Total_monthly_fuel_expense ]]<-4760),"Outlier","Normal") -> Normal
A9: 26 | B9: Male | C9: 10,000 - 30,000 | D9: 6 | E9: 1 | F9: bikes | G9: Petrol | K9: 8 | L9: 40 | M9: 28 | W9: 3000 | X9: Indian Oil | Y9: 18 | Z9: Market/Shopping | AA9: Weekly | AB9: Bus | AC9: Maybe | AD9: =IF(OR(Form_Responses34[[#This Row],[Total_monthly_fuel_expense ]]>10040,Form_Responses34[[#This Row],[Total_monthly_fuel_expense ]]<-4760),"Outlier","Normal") -> Normal
A10: 23 | B10: Female | C10: 30,000 - 50,000 | D10: 3 | E10: 1 | F10: Scooty | H10: Petrol | N10: 3 | O10: 18 | P10: 12 | W10: 1500 | X10: BPCL | Y10: 7 | Z10: Office | AA10: Weekly | AB10: Auto | AC10: Maybe | AD10: =IF(OR(Form_Responses34[[#This Row],[Total_monthly_fuel_expense ]]>10040,Form_Responses34[[#This Row],[Total_monthly_fuel_expense ]]<-4760),"Outlier","Normal") -> Normal
A11: 32 | B11: Male | C11: above 1,00,000 | D11: 4 | E11: 2 | F11: car, Electric Vehicle | I11: Petrol | Q11: 3 | R11: 40 | S11: 60 | W11: 9500 | X11: Reliance | Y11: 20 | Z11: Office | AA11: Never | AB11: I don’t use public transport | AC11: Yes | AD11: =IF(OR(Form_Responses34[[#This Row],[Total_monthly_fuel_expense ]]>10040,Form_Responses34[[#This Row],[Total_monthly_fuel_expense ]]<-4760),"Outlier","Normal") -> Normal
A12: 19 | B12: Male | C12: below 10,000 | D12: 3 | E12: 1 | F12: Scooty | H12: Petrol | N12: 1 | O12: 10 | P12: 8 | W12: 1500 | X12: BPCL | Y12: 5 | Z12: College | AA12: Weekly | AB12: Shared Rickshaw | AC12: Maybe | AD12: =IF(OR(Form_Responses34[[#This Row],[Total_monthly_fuel_expense ]]>10040,Form_Responses34[[#This Row],[Total_monthly_fuel_expense ]]<-4760),"Outlier","Normal") -> Normal
A13: 27 | B13: Male | C13: 30,000 - 50,000 | D13: 5 | E13: 2 | F13: bikes, Commercial vehicle | G13: Petrol | J13: Diesel | K13: 6 | L13: 15 | M13: 10 | T13: 5 | U13: 25 | V13: 70 | W13: 8000 | X13: HP | Y13: 14 | Z13: Agriculture-related | AA13: Rarely | AB13: Bus | AC13: No | AD13: =IF(OR(Form_Responses34[[#This Row],[Total_monthly_fuel_expense ]]>10040,Form_Responses34[[#This Row],[Total_monthly_fuel_expense ]]<-4760),"Outlier","Normal") -> Normal
A14: 23 | B14: Female | C14: 50,000 - 70,000 | D14: 4 | E14: 2 | F14: bikes, car | G14: Petrol | I14: Petrol | K14: 3 | L14: 20 | M14: 12 | Q14: 4 | R14: 30 | S14: 55 | W14: 6800 | X14: Indian Oil | Y14: 10 | Z14: Work | AA14: Monthly | AB14: Bus | AC14: Maybe | AD14: =IF(OR(Form_Responses34[[#This Row],[Total_monthly_fuel_expense ]]>10040,Form_Responses34[[#This Row],[Total_monthly_fuel_expense ]]<-4760),"Outlier","Normal") -> Normal
A15: 26 | B15: Male | C15: 50,000 - 70,000 | D15: 4 | E15: 2 | F15: bikes, car | G15: Petrol | I15: Petrol | K15: 5 | L15: 10 | M15: 7 | Q15: 2 | R15: 45 | S15: 70 | W15: 9000 | X15: HP | Y15: 18 | Z15: Office | AA15: Rarely | AB15: I don’t use public transport | AC15: Yes | AD15: =IF(OR(Form_Responses34[[#This Row],[Total_monthly_fuel_expense ]]>10040,Form_Responses34[[#This Row],[Total_monthly_fuel_expense ]]<-4760),"Outlier","Normal") -> Normal
A16: 30 | B16: Male | C16: 30,000 - 50,000 | D16: 5 | E16: 3 | F16: bikes, Scooty, car | G16: Petrol | H16: Petrol | I16: Petrol | K16: 4 | L16: 18 | M16: 13 | N16: 2 | O16: 12 | P16: 9 | Q16: 5 | R16: 40 | S16: 65 | W16: 9000 | X16: BPCL | Y16: 15 | Z16: Office | AA16: Rarely | AB16: Auto | AC16: Yes | AD16: =IF(OR(Form_Responses34[[#This Row],[Total_monthly_fuel_expense ]]>10040,Form_Responses34[[#This Row],[Total_monthly_fuel_expense ]]<-4760),"Outlier","Normal") -> Normal
A17: 21 | B17: Female | C17: below 10,000 | D17: 4 | E17: 1 | F17: Scooty | H17: Petrol | N17: 1 | O17: 10 | P17: 7 | W17: 900 | X17: BPCL | Y17: 5 | Z17: College | AA17: Weekly | AB17: Shared Rickshaw | AC17: Maybe | AD17: =IF(OR(Form_Responses34[[#This Row],[Total_monthly_fuel_expense ]]>10040,Form_Responses34[[#This Row],[Total_monthly_fuel_expense ]]<-4760),"Outlier","Normal") -> Normal
A18: 20 | B18: Male | C18: below 10,000 | D18: 5 | E18: 3 | F18: bikes, car | G18: Petrol | I18: Petrol | K18: 8 | L18: 3 | M18: 6 | Q18: 7 | R18: 10 | S18: 25 | W18: 2000 | X18: HP | Y18: 9 | Z18: Office | AA18: Daily | AB18: Bus, Shared Rickshaw | AC18: Yes | AD18: =IF(OR(Form_Responses34[[#This Row],[Total_monthly_fuel_expense ]]>10040,Form_Responses34[[#This Row],[Total_monthly_fuel_expense ]]<-4760),"Outlier","Normal") -> Normal
A19: 25 | B19: Male | C19: 30,000 - 50,000 | D19: 3 | E19: 1 | F19: bikes | G19: Petrol | K19: 3 | L19: 22 | M19: 18 | W19: 2300 | X19: Indian Oil | Y19: 10 | Z19: Office | AA19: Monthly | AB19: Bus | AC19: Maybe | AD19: =IF(OR(Form_Responses34[[#This Row],[Total_monthly_fuel_expense ]]>10040,Form_Responses34[[#This Row],[Total_monthly_fuel_expense ]]<-4760),"Outlier","Normal") -> Normal
A20: 19 | B20: Female | C20: below 10,000 | D20: 4 | E20: 1 | F20: Scooty | H20: Petrol | N20: 2 | O20: 15 | P20: 10 | W20: 1200 | X20: BPCL | Y20: 6 | Z20: College | AA20: Weekly | AB20: Shared Rickshaw | AC20: Yes | AD20: =IF(OR(Form_Responses34[[#This Row],[Total_monthly_fuel_expense ]]>10040,Form_Responses34[[#This Row],[Total_monthly_fuel_expense ]]<-4760),"Outlier","Normal") -> Normal
A21: 35 | B21: Male | C21: 30,000 - 50,000 | D21: 6 | E21: 3 | F21: bikes, Commercial vehicle, Tractor | G21: Petrol | J21: Diesel | K21: 10 | L21: 15 | M21: 10 | T21: 8 | U21: 35 | V21: 80 | W21: 11100 | X21: Indian Oil | Y21: 12 | Z21: Agriculture-related | AA21: Rarely | AB21: Bus | AC21: No | AD21: =IF(OR(Form_Responses34[[#This Row],[Total_monthly_fuel_expense ]]>10040,Form_Responses34[[#This Row],[Total_monthly_fuel_expense ]]<-4760),"Outlier","Normal") -> Outlier
A22: 24 | B22: Female | C22: 30,000 - 50,000 | D22: 3 | E22: 1 | F22: car | I22: Petrol | Q22: 2 | R22: 30 | S22: 50 | W22: 6000 | X22: Shell | Y22: 10 | Z22: Office | AA22: Monthly | AB22: Bus | AC22: Yes | AD22: =IF(OR(Form_Responses34[[#This Row],[Total_monthly_fuel_expense ]]>10040,Form_Responses34[[#This Row],[Total_monthly_fuel_expense ]]<-4760),"Outlier","Normal") -> Normal
A23: 31 | B23: Male | C23: 70,000 - 1,00,000 | D23: 5 | E23: 3 | F23: bikes, car, Electric Vehicle | G23: Petrol | I23: Petrol | K23: 4 | L23: 8 | M23: 6 | Q23: 6 | R23: 35 | S23: 55 | W23: 8800 | X23: Shell | Y23: 14 | Z23: Office | AA23: Never | AB23: I don’t use public transport | AC23: Yes | AD23: =IF(OR(Form_Responses34[[#This Row],[Total_monthly_fuel_expense ]]>10040,Form_Responses34[[#This Row],[Total_monthly_fuel_expense ]]<-4760),"Outlier","Normal") -> Normal
A24: 27 | B24: Male | C24: below 10,000 | D24: 4 | E24: 1 | F24: bikes | G24: Petrol | K24: 6 | L24: 35 | M24: 24 | W24: 2700 | X24: BPCL | Y24: 14 | Z24: Other | AA24: Weekly | AB24: Bus | AC24: Maybe | AD24: =IF(OR(Form_Responses34[[#This Row],[Total_monthly_fuel_expense ]]>10040,Form_Responses34[[#This Row],[Total_monthly_fuel_expense ]]<-4760),"Outlier","Normal") -> Normal
A25: 27 | B25: Female | C25: 10,000 - 30,000 | D25: 6 | E25: 2 | F25: bikes, Scooty | G25: Petrol | H25: Petrol | K25: 5 | L25: 12 | M25: 9 | N25: 3 | O25: 10 | P25: 8 | W25: 3000 | X25: Indian Oil | Y25: 4 | Z25: Market/Shopping | AA25: Weekly | AB25: Auto | AC25: Maybe | AD25: =IF(OR(Form_Responses34[[#This Row],[Total_monthly_fuel_expense ]]>10040,Form_Responses34[[#This Row],[Total_monthly_fuel_expense ]]<-4760),"Outlier","Normal") -> Normal
A26: 28 | B26: Female | C26: 10,000 - 30,000 | D26: 5 | E26: 2 | F26: Scooty, car | H26: Petrol | I26: Petrol | N26: 5 | O26: 12 | P26: 9 | Q26: 8 | R26: 20 | S26: 40 | W26: 5200 | X26: Indian Oil | Y26: 8 | Z26: School pickup/drop | AA26: Rarely | AB26: Auto | AC26: No | AD26: =IF(OR(Form_Responses34[[#This Row],[Total_monthly_fuel_expense ]]>10040,Form_Responses34[[#This Row],[Total_monthly_fuel_expense ]]<-4760),"Outlier","Normal") -> Normal
A27: 34 | B27: Male | C27: 50,000 - 70,000 | D27: 4 | E27: 2 | F27: bikes, car | G27: Petrol | I27: Diesel | K27: 7 | L27: 10 | M27: 7 | Q27: 4 | R27: 50 | S27: 70 | W27: 9700 | X27: BPCL | Y27: 15 | Z27: Office | AA27: Rarely | AB27: Train | AC27: Maybe | AD27: =IF(OR(Form_Responses34[[#This Row],[Total_monthly_fuel_expense ]]>10040,Form_Responses34[[#This Row],[Total_monthly_fuel_expense ]]<-4760),"Outlier","Normal") -> Normal
A28: 30 | B28: Female | C28: 30,000 - 50,000 | D28: 5 | E28: 2 | F28: bikes, Commercial vehicle | G28: Petrol | J28: Diesel | K28: 6 | L28: 18 | M28: 12 | T28: 10 | U28: 25 | V28: 65 | W28: 8200 | X28: Indian Oil | Y28: 8 | Z28: Agriculture-related | AA28: Monthly | AB28: Bus | AC28: No | AD28: =IF(OR(Form_Responses34[[#This Row],[Total_monthly_fuel_expense ]]>10040,Form_Responses34[[#This Row],[Total_monthly_fuel_expense ]]<-4760),"Outlier","Normal") -> Normal
A29: 22 | B29: Male | C29: 10,000 - 30,000 | D29: 3 | E29: 1 | F29: bikes | G29: Petrol | K29: 2 | L29: 30 | M29: 20 | W29: 2400 | X29: HP | Y29: 7 | Z29: College | AA29: Weekly | AB29: Bus | AC29: Yes | AD29: =IF(OR(Form_Responses34[[#This Row],[Total_monthly_fuel_expense ]]>10040,Form_Responses34[[#This Row],[Total_monthly_fuel_expense ]]<-4760),"Outlier","Normal") -> Normal
A30: 28 | B30: Male | C30: below 10,000 | D30: 4 | E30: 1 | F30: bikes | G30: Petrol | K30: 8 | L30: 40 | M30: 26 | W30: 2900 | X30: BPCL | Y30: 12 | Z30: Other | AA30: Monthly | AB30: Bus | AC30: Maybe | AD30: =IF(OR(Form_Responses34[[#This Row],[Total_monthly_fuel_expense ]]>10040,Form_Responses34[[#This Row],[Total_monthly_fuel_expense ]]<-4760),"Outlier","Normal") -> Normal
A31: 33 | B31: Male | C31: 50,000 - 70,000 | D31: 6 | E31: 3 | F31: bikes, Scooty, car | G31: Petrol | H31: Petrol | I31: Petrol | K31: 4 | L31: 25 | M31: 16 | N31: 3 | O31: 8 | P31: 6 | Q31: 5 | R31: 40 | S31: 60 | W31: 9500 | X31: HP | Y31: 20 | Z31: Office | AA31: Rarely | AB31: Bus | AC31: Yes | AD31: =IF(OR(Form_Responses34[[#This Row],[Total_monthly_fuel_expense ]]>10040,Form_Responses34[[#This Row],[Total_monthly_fuel_expense ]]<-4760),"Outlier","Normal") -> Normal
A32: 26 | B32: Female | C32: 30,000 - 50,000 | D32: 3 | E32: 1 | F32: car | I32: Petrol | Q32: 3 | R32: 25 | S32: 45 | W32: 5200 | X32: Indian Oil | Y32: 9 | Z32: Office | AA32: Monthly | AB32: Auto | AC32: Yes | AD32: =IF(OR(Form_Responses34[[#This Row],[Total_monthly_fuel_expense ]]>10040,Form_Responses34[[#This Row],[Total_monthly_fuel_expense ]]<-4760),"Outlier","Normal") -> Normal
A33: 30 | B33: Male | C33: 70,000 - 1,00,000 | D33: 4 | E33: 2 | F33: bikes, car | G33: Petrol | I33: Diesel | K33: 2 | L33: 10 | M33: 7 | Q33: 3 | R33: 50 | S33: 65 | W33: 8500 | X33: BPCL | Y33: 18 | Z33: Office | AA33: Rarely | AB33: I don’t use public transport | AC33: Maybe | AD33: =IF(OR(Form_Responses34[[#This Row],[Total_monthly_fuel_expense ]]>10040,Form_Responses34[[#This Row],[Total_monthly_fuel_expense ]]<-4760),"Outlier","Normal") -> Normal
A34: 33 | B34: Male | C34: 10,000 - 30,000 | D34: 5 | E34: 2 | F34: bikes, Commercial vehicle | G34: Petrol | J34: Diesel | K34: 9 | L34: 20 | M34: 14 | T34: 12 | U34: 18 | V34: 55 | W34: 7000 | X34: HP | Y34: 10 | Z34: Agriculture-related | AA34: Rarely | AB34: Private Bus | AC34: No | AD34: =IF(OR(Form_Responses34[[#This Row],[Total_monthly_fuel_expense ]]>10040,Form_Responses34[[#This Row],[Total_monthly_fuel_expense ]]<-4760),"Outlier","Normal") -> Normal
A35: 38 | B35: Male | C35: 50,000 - 70,000 | D35: 5 | E35: 2 | F35: bikes, car | G35: Petrol | I35: Petrol | K35: 9 | L35: 15 | M35: 12 | Q35: 4 | R35: 20 | S35: 24 | W35: 5500 | X35: Reliance | Y35: 12 | Z35: Other | AA35: Never | AB35: I don’t use public transport | AC35: No | AD35: =IF(OR(Form_Responses34[[#This Row],[Total_monthly_fuel_expense ]]>10040,Form_Responses34[[#This Row],[Total_monthly_fuel_expense ]]<-4760),"Outlier","Normal") -> Normal
A36: 29 | B36: Female | C36: 30,000 - 50,000 | D36: 3 | E36: 1 | F36: Scooty | H36: Petrol | N36: 3 | O36: 9 | P36: 7 | W36: 900 | X36: Indian Oil | Y36: 4 | Z36: Office | AA36: Monthly | AB36: Auto | AC36: Yes | AD36: =IF(OR(Form_Responses34[[#This Row],[Total_monthly_fuel_expense ]]>10040,Form_Responses34[[#This Row],[Total_monthly_fuel_expense ]]<-4760),"Outlier","Normal") -> Normal
A37: 26 | B37: Male | C37: 10,000 - 30,000 | D37: 6 | E37: 2 | F37: bikes, Commercial vehicle | G37: Petrol | J37: Diesel | K37: 4 | L37: 14 | M37: 10 | T37: 7 | U37: 32 | V37: 42 | W37: 5200 | X37: HP | Y37: 10 | Z37: Agriculture-related | AA37: Rarely | AB37: Bus | AC37: Maybe | AD37: =IF(OR(Form_Responses34[[#This Row],[Total_monthly_fuel_expense ]]>10040,Form_Responses34[[#This Row],[Total_monthly_fuel_expense ]]<-4760),"Outlier","Normal") -> Normal
A38: 20 | B38: Female | C38: below 10,000 | D38: 4 | E38: 1 | F38: Scooty | H38: Petrol | N38: 1 | O38: 8 | P38: 5 | W38: 650 | X38: BPCL | Y38: 5 | Z38: College | AA38: Weekly | AB38: Bus | AC38: Yes | AD38: =IF(OR(Form_Responses34[[#This Row],[Total_monthly_fuel_expense ]]>10040,Form_Responses34[[#This Row],[Total_monthly_fuel_expense ]]<-4760),"Outlier","Normal") -> Normal
A39: 42 | B39: Male | C39: 70,000 - 1,00,000 | D39: 5 | E39: 3 | F39: bikes, car, Commercial vehicle | G39: Petrol | I39: Petrol | J39: Diesel | K39: 8 | L39: 20 | M39: 15 | Q39: 5 | R39: 22 | S39: 26 | T39: 6 | U39: 45 | V39: 26 | W39: 12000 | X39: Indian Oil | Y39: 15 | Z39: Office | AA39: Never | AB39: I don’t use public transport | AC39: Maybe | AD39: =IF(OR(Form_Responses34[[#This Row],[Total_monthly_fuel_expense ]]>10040,Form_Responses34[[#This Row],[Total_monthly_fuel_expense ]]<-4760),"Outlier","Normal") -> Outlier
A40: 31 | B40: Female | C40: 50,000 - 70,000 | D40: 4 | E40: 1 | F40: car | I40: Petrol | Q40: 3 | R40: 16 | S40: 20 | W40: 2400 | X40: Shell | Y40: 6 | Z40: Office | AA40: Rarely | AB40: Auto | AC40: Yes | AD40: =IF(OR(Form_Responses34[[#This Row],[Total_monthly_fuel_expense ]]>10040,Form_Responses34[[#This Row],[Total_monthly_fuel_expense ]]<-4760),"Outlier","Normal") -> Normal
...

Sheet Clean_Data_Summary
A5: Colunm | B5: (clean data)blank | C5: Min | D5: max | E5: Average | F5: median | G5: MODE | H5: count
A6: fuel_required_Bike | B6: =COUNTBLANK(Form_Responses34[fuel_required_Bike ]) -> 212 | H6: =COUNTA(Form_Responses34[fuel_required_Bike ]) -> 355
A7: fuel_required_Scooty | B7: =COUNTBLANK(Form_Responses34[fuel_required_Scooty ]) -> 402 | H7: =COUNTA(Form_Responses34[fuel_required_Scooty ]) -> 165
A8: fuel_required_Car | B8: =COUNTBLANK(Form_Responses34[fuel_required_Car ]) -> 398 | H8: =COUNTA(Form_Responses34[fuel_required_Car ]) -> 169
A9: fuel_required_Commercial | B9: =COUNTBLANK(Form_Responses34[fuel_required_Commercial ]) -> 481 | H9: =COUNTA(Form_Responses34[fuel_required_Commercial ]) -> 86
A10: Age_bike | B10: =COUNTBLANK(Form_Responses34[Age_bike ]) -> 212 | C10: =MIN(clean_data!K2:K568) -> 1 | D10: =MAX(clean_data!K2:K568) -> 38 | E10: =AVEDEV(clean_data!K2:K568) -> 3.4466177 | F10: =MEDIAN(clean_data!K2:K568) -> 6 | G10: =_xlfn.MODE.MULT(clean_data!K2:K568) -> 6 | H10: =COUNT(Form_Responses34[Age_bike ]) -> 355 | I10: year
A11: Daily_distance_travelled_bike | B11: =COUNTBLANK(Form_Responses34[Daily_distance_travelled_bike ]) -> 212 | C11: =MIN(clean_data!L2:L568) -> 1 | D11: =MAX(clean_data!L2:L569) -> 120 | E11: =AVEDEV(clean_data!L2:L569) -> 6.3055743 | F11: =MEDIAN(clean_data!L2:L569) -> 12 | G11: =_xlfn.MODE.MULT(clean_data!L2:L569) -> 10 | H11: =COUNT(Form_Responses34[Daily_distance_travelled_bike ]) -> 355 | I11: km
A12: fuel_monthly_bike | B12: =COUNTBLANK(Form_Responses34[fuel_monthly_bikes]) -> 212 | C12: =MIN(clean_data!M2:M568) -> 1 | D12: =MAX(clean_data!M2:M568) -> 90 | E12: =AVEDEV(clean_data!M2:M570) -> 5.6650347 | F12: =MEDIAN(clean_data!M2:M570) -> 8 | G12: =_xlfn.MODE.MULT(clean_data!M2:M570) -> 5 | H12: =COUNT(Form_Responses34[fuel_monthly_bikes]) -> 355 | I12: lit
A13: Age_Scooty | B13: =COUNTBLANK(Form_Responses34[Age_Scooty]) -> 402 | C13: =MIN(clean_data!N2:N568) -> 1 | D13: =MAX(clean_data!N2:N568) -> 25 | E13: =AVEDEV(clean_data!N2:N571) -> 1.9023691 | F13: =MEDIAN(clean_data!N2:N571) -> 3 | G13: =_xlfn.MODE.MULT(clean_data!N2:N571) -> 3 | H13: =COUNT(Form_Responses34[Age_Scooty]) -> 165 | I13: yrs
A14: Daily_distance_travelled_Scooty | B14: =COUNTBLANK(Form_Responses34[Daily_distance_travelled_Scooty ]) -> 402 | C14: =MIN(clean_data!O2:O572) -> 1 | D14: =MAX(clean_data!O2:O568) -> 50 | E14: =AVEDEV(clean_data!O2:O572) -> 3.4461708 | F14: =MEDIAN(clean_data!O2:O572) -> 8 | G14: =_xlfn.MODE.MULT(clean_data!O2:O572) -> 10 | H14: =COUNT(Form_Responses34[Daily_distance_travelled_Scooty ]) -> 165 | I14: km
A15: Fuel_required_monthly_scooty | B15: =COUNTBLANK(Form_Responses34[Fuel_required_monthly_scooty]) -> 402 | C15: =MIN(clean_data!P2:P572) -> 2 | D15: =MAX(clean_data!P2:P568) -> 46 | E15: =AVEDEV(clean_data!P2:P573) -> 3.2916804 | F15: =MEDIAN(clean_data!P2:P573) -> 6 | G15: =_xlfn.MODE.MULT(clean_data!P2:P573) -> 5 | H15: =COUNT(Form_Responses34[Fuel_required_monthly_scooty]) -> 165 | I15: lit
A16: Age_Car | B16: =COUNTBLANK(Form_Responses34[[#All],[ Age_Car]]) -> 398 | C16: =MIN(clean_data!Q6:Q572) -> 1 | D16: =MAX(clean_data!Q2:Q568) -> 13 | E16: =AVEDEV(clean_data!Q2:Q574) -> 1.5685025 | F16: =MEDIAN(clean_data!Q2:Q574) -> 5 | G16: =_xlfn.MODE.MULT(clean_data!Q2:Q574) -> 5 | H16: =COUNT(Form_Responses34[[#All],[ Age_Car]]) -> 169 | I16: yrs
A17: Daily_distance_travelled_Car | B17: =COUNTBLANK(Form_Responses34[Daily_distance_travelled_Car ]) -> 398 | C17: =MIN(clean_data!R2:R572) -> 8 | D17: =MAX(clean_data!R2:R568) -> 100 | E17: =AVEDEV(clean_data!R2:R575) -> 5.7728371 | F17: =MEDIAN(clean_data!R2:R575) -> 24 | G17: =_xlfn.MODE.MULT(clean_data!R2:R575) -> 25 | H17: =COUNT(Form_Responses34[Daily_distance_travelled_Car ]) -> 169 | I17: km
A18: Fuel_required_monthly_car | B18: =COUNTBLANK(Form_Responses34[Fuel_required_monthly_car]) -> 398 | C18: =MIN(clean_data!S2:S576) -> 5 | D18: =MAX(clean_data!S2:S568) -> 70 | E18: =AVEDEV(clean_data!S2:S576) -> 7.6939883 | F18: =MEDIAN(clean_data!S2:S576) -> 24 | G18: =_xlfn.MODE.MULT(clean_data!S2:S576) -> 22 | H18: =COUNT(Form_Responses34[Fuel_required_monthly_car]) -> 169 | I18: lit
A19: Age_commercial | B19: =COUNTBLANK(Form_Responses34[[#All],[ Age_commercial]]) -> 481 | C19: =MIN(clean_data!T10:T576) -> 2 | D19: =MAX(clean_data!T2:T568) -> 24 | E19: =AVEDEV(clean_data!T2:T577) -> 3.8658734 | F19: =MEDIAN(clean_data!T2:T577) -> 12 | G19: =_xlfn.MODE.MULT(clean_data!T2:T577) -> 10 | H19: =COUNT(Form_Responses34[[#All],[ Age_commercial]]) -> 86 | I19: yrs
A20: Daily_distance_travelled_commercial | B20: =COUNTBLANK(Form_Responses34[Daily_distance_travelled_commercial]) -> 481 | C20: =MIN(clean_data!U10:U576) -> 0 | D20: =MAX(clean_data!U2:U568) -> 75 | E20: =AVEDEV(clean_data!U2:U578) -> 13.777177 | F20: =MEDIAN(clean_data!U2:U578) -> 45 | G20: =_xlfn.MODE.MULT(clean_data!U2:U578) -> 45 | H20: =COUNT(Form_Responses34[Daily_distance_travelled_commercial]) -> 86 | I20: km
A21: Fuel_required_monthly_commercial | B21: =COUNTBLANK(Form_Responses34[Fuel_required_monthly_commercial]) -> 481 | C21: =MIN(clean_data!V2:V576) -> 1 | D21: =MAX(clean_data!V2:V568) -> 110 | E21: =AVEDEV(clean_data!V2:V579) -> 16.092482 | F21: =MEDIAN(clean_data!V2:V579) -> 70 | G21: =_xlfn.MODE.MULT(clean_data!V2:V579) -> 70 | H21: =COUNT(Form_Responses34[Fuel_required_monthly_commercial]) -> 86 | I21: lit
A22: Total_monthly_fuel_expense | B22: =COUNTBLANK(Form_Responses34[Total_monthly_fuel_expense ]) -> 0 | C22: =MIN(clean_data!W2:W580) -> 200 | D22: =MAX(clean_data!W2:W568) -> 20000 | E22: =AVEDEV(clean_data!W2:W580) -> 2704.8788 | F22: =MEDIAN(clean_data!W2:W580) -> 1600 | G22: =_xlfn.MODE.MULT(clean_data!W2:W580) -> 650 | H22: =COUNT(Form_Responses34[Total_monthly_fuel_expense ]) -> 567 | I22: rs
A26: SUMMARY
A27: Avg Monthly Fuel Expense per Household | B27: =AVERAGE(Form_Responses34[Total_monthly_fuel_expense ]) -> 3336.4427

Sheet Outlier_detection
A1: Summary sheet for outliers - calculate fences
A2: Q1 | B2: =QUARTILE(Form_Responses34[Total_monthly_fuel_expense ],1) -> 790
A3: Q3 | B3: =QUARTILE(Form_Responses34[Total_monthly_fuel_expense ],3) -> 4490
A4: IQR | B4: =B3-B2 -> 3700
A5: Lower fence | B5: =B2-1.5*B4 -> -4760
A6: Upper fence | B6: =B3+1.5*B4 -> 10040
A7: High outliers | B7: =COUNTIF(Form_Responses34[Total_monthly_fuel_expense ],">"&Outlier_detection!B6) -> 35
A8: Low outliers | B8: =COUNTIF(Form_Responses34[Total_monthly_fuel_expense ],"<"&Outlier_detection!B5) -> 0

Sheet Descriptive_Statistics
A1: Discriptive Statistics Table
A3: Variable | B3: N | C3: Mean | D3: Median | E3: SD | F3: Min | G3: Max | H3: Skewness | I3: Distribution Type
A4: Total_Fuel_Expense | B4: 567 | C4: =AVERAGE(Form_Responses34[Total_monthly_fuel_expense ]) -> 3336.4427 | D4: =MEDIAN(Form_Responses34[Total_monthly_fuel_expense ]) -> 1600 | E4: =STDEV(Form_Responses34[Total_monthly_fuel_expense ]) -> 3508.029 | F4: =MIN(Form_Responses34[Total_monthly_fuel_expense ]) -> 200 | G4: =MAX(Form_Responses34[Total_monthly_fuel_expense ]) -> 20000 | H4: =SKEW(Form_Responses34[Total_monthly_fuel_expense ]) -> 1.6117876 | I4: Strongly right-skewed
A5: Per_Capita_Fuel | B5: 567 | C5: 750 | D5: 400 | E5: 763 | F5: 40 | G5: 5000 | H5: =SKEW(Per_Capita_Expenses!C1:C568) -> 1.7721822 | I5: Strongly right-skewed
A6: Num_Vehicles | B6: 567 | C6: =AVERAGE(Form_Responses34[Num_vehicles_in_family ]) -> 1.4409171 | D6: =MEDIAN(Form_Responses34[Num_vehicles_in_family ]) -> 1 | E6: =STDEV(Form_Responses34[Num_vehicles_in_family ]) -> 0.62595612 | F6: =MIN(Form_Responses34[Num_vehicles_in_family ]) -> 1 | G6: =MAX(Form_Responses34[Num_vehicles_in_family ]) -> 4 | H6: =SKEW(Form_Responses34[Num_vehicles_in_family ]) -> 1.1570272 | I6: Strongly right-skewed
A7: Family_Members | B7: 567 | C7: =AVERAGE(Form_Responses34[Total_family _members ]) -> 4.4620811 | D7: =MEDIAN(Form_Responses34[Total_family _members ]) -> 4 | E7: =STDEV(Form_Responses34[Total_family _members ]) -> 0.99017679 | F7: =MIN(Form_Responses34[Total_family _members ]) -> 2 | G7: =MAX(Form_Responses34[Total_family _members ]) -> 10 | H7: =SKEW(Form_Responses34[Total_family _members ]) -> 0.29729671 | I7: Approximately symmetric
A8: Home_Work_Distance | B8: 567 | C8: =AVERAGE(Form_Responses34[Distance_home_ workplace]) -> 8.340388 | D8: =MEDIAN(Form_Responses34[Distance_home_ workplace]) -> 7 | E8: =STDEV(Form_Responses34[Distance_home_ workplace]) -> 4.9046212 | F8: =MIN(Form_Responses34[Distance_home_ workplace]) -> 1 | G8: =MAX(Form_Responses34[Distance_home_ workplace]) -> 40 | H8: =SKEW(Form_Responses34[Distance_home_ workplace]) -> 1.7491891 | I8: Strongly right-skewed

Sheet Pie_Chart
A1: Vehicle type | B1: counts
A2: Bike | B2: =COUNTIF('Fuel_Data_Used_Avg_Fuel(l)'!G2:G568,1) -> 355
A3: Car | B3: =COUNTIF('Fuel_Data_Used_Avg_Fuel(l)'!H2:H568,1) -> 165
A4: Scooty | B4: =COUNTIF('Fuel_Data_Used_Avg_Fuel(l)'!I2:I568,1) -> 169
A5: Commercial Vehicle | B5: =COUNTIF('Fuel_Data_Used_Avg_Fuel(l)'!J2:J568,1) -> 86

Sheet Box_plot
A2: Summary for Box Plot | G2: Segment heights for Box Plot
A3: Statistic | B3: 1 Vehicle | C3: 2 Vehicle | D3: 3 Vehicle | E3: 4 Vehicle | G3: Statistic | H3: 1 Vehicle | I3: 2 Vehicle | J3: 3 Vehicle
A4: Min | B4: =MIN(ANOVA1!D:D) -> 260 | C4: =MIN(ANOVA1!E:E) -> 330 | D4: =MIN(ANOVA1!F:F) -> 200 | E4: =MIN(ANOVA1!G:G) -> 15000 | G4: Min | H4: 260 | I4: 330 | J4: 200
A5: Q1 | B5: =QUARTILE(ANOVA1!D:D,1) -> 650 | C5: =QUARTILE(ANOVA1!E:E,1) -> 3600 | D5: =QUARTILE(ANOVA1!F:F,1) -> 5125 | E5: =QUARTILE(ANOVA1!G:G,1) -> 15000 | G5: Q1 | H5: =650-H4 -> 390 | I5: =3600-I4 -> 3270 | J5: =5125-J4 -> 4925
A6: Median | B6: =QUARTILE(ANOVA1!D:D,2) -> 1000 | C6: =QUARTILE(ANOVA1!E:E,2) -> 4800 | D6: =QUARTILE(ANOVA1!F:F,2) -> 9450 | E6: =QUARTILE(ANOVA1!G:G,2) -> 15000 | G6: Median | H6: =1000-650 -> 350 | I6: =4800-3600 -> 1200 | J6: =9450-5125 -> 4325
A7: Q3 | B7: =QUARTILE(ANOVA1!D:D,3) -> 1800 | C7: =QUARTILE(ANOVA1!E:E,3) -> 8050 | D7: =QUARTILE(ANOVA1!F:F,3) -> 12000 | E7: =QUARTILE(ANOVA1!G:G,3) -> 15000 | G7: Q3 | H7: =1800-1000 -> 800 | I7: =8050-4800 -> 3250 | J7: =12000-9450 -> 2550
A8: Max | B8: =MAX(ANOVA1!D:D) -> 20000 | C8: =MAX(ANOVA1!E:E) -> 20000 | D8: =MAX(ANOVA1!F:F) -> 15600 | E8: =MAX(ANOVA1!G:G) -> 15000 | G8: Max | H8: =20000-1800 -> 18200 | I8: =20000-8050 -> 11950 | J8: =15600-12000 -> 3600
B11: Invisible | C11: Lower Whisker | D11: IQR Lower | E11: IQR Upper | F11: Upper Whisker
A12: 1 Vehicle | B12: 260 | C12: 390 | D12: 350 | E12: 800 | F12: 18200
A13: 2 Vehicle | B13: 330 | C13: 3270 | D13: 1200 | E13: 3250 | F13: 11950
A14: 3 Vehicle | B14: 200 | C14: 4925 | D14: 4325 | E14: 2550 | F14: 3600

Sheet Pivot_Charts
A1: Pivot 1 | G1: Pivot 2
A2: Row Labels | B2: Sum of Has_Bike | C2: Sum of Has_Car | D2: Sum of Has_Scooty | E2: Sum of Has_Commercial | G2: Row Labels | H2: Count of Total_monthly_fuel_expense
A3: Female | B3: 85 | C3: 41 | D3: 146 | E3: 2 | G3: 10,000-30,000 | H3: 101
A4: Male | B4: 270 | C4: 128 | D4: 19 | E4: 84 | G4: 30,000-50,000 | H4: 203
A5: Grand Total | B5: 355 | C5: 169 | D5: 165 | E5: 86 | G5: 50,000-70,000 | H5: 98
G6: 70,000-1,00,000 | H6: 23
G7: above 1,00,000 | H7: 17
G8: below 10,000 | H8: 125
G9: (blank)
G10: Grand Total | H10: 567

Sheet Fuel_Data_Used_Avg_Fuel(l)
A1: Type_vehicle | B1: fuel_monthly_bikes | C1: Fuel_required_monthly_scooty | D1: Fuel_required_monthly_car | E1: Fuel_required_monthly_commercial | F1: Total_monthly_fuel_expense | G1: Has_Bike | H1: Has_Scooty | I1: Has_Car | J1: Has_Commercial | K1: Has_EV | L1: Gender
A2: bikes | B2: 30 | F2: 3000 | G2: =IF(ISNUMBER(SEARCH("bike",A2)),1,0) -> 1 | H2: =IF(ISNUMBER(SEARCH("Scooty",A2)),1,0) -> 0 | I2: =IF(ISNUMBER(SEARCH("Car",A2)),1,0) -> 0 | J2: =IF(ISNUMBER(SEARCH("Commercial vehicle",A2)),1,0) -> 0 | K2: =IF(ISNUMBER(SEARCH("Electric Vehicle",A2)),1,0) -> 0 | L2: Female
A3: bikes, Commercial vehicle | B3: 75 | E3: 1 | F3: 9200 | G3: =IF(ISNUMBER(SEARCH("bike",A3)),1,0) -> 1 | H3: =IF(ISNUMBER(SEARCH("Scooty",A3)),1,0) -> 0 | I3: =IF(ISNUMBER(SEARCH("Car",A3)),1,0) -> 0 | J3: =IF(ISNUMBER(SEARCH("Commercial vehicle",A3)),1,0) -> 1 | K3: =IF(ISNUMBER(SEARCH("Electric Vehicle",A3)),1,0) -> 0 | L3: Male
A4: Scooty | C4: 10 | F4: 1000 | G4: =IF(ISNUMBER(SEARCH("bike",A4)),1,0) -> 0 | H4: =IF(ISNUMBER(SEARCH("Scooty",A4)),1,0) -> 1 | I4: =IF(ISNUMBER(SEARCH("Car",A4)),1,0) -> 0 | J4: =IF(ISNUMBER(SEARCH("Commercial vehicle",A4)),1,0) -> 0 | K4: =IF(ISNUMBER(SEARCH("Electric Vehicle",A4)),1,0) -> 0 | L4: Female
A5: bikes | B5: 20 | F5: 1000 | G5: =IF(ISNUMBER(SEARCH("bike",A5)),1,0) -> 1 | H5: =IF(ISNUMBER(SEARCH("Scooty",A5)),1,0) -> 0 | I5: =IF(ISNUMBER(SEARCH("Car",A5)),1,0) -> 0 | J5: =IF(ISNUMBER(SEARCH("Commercial vehicle",A5)),1,0) -> 0 | K5: =IF(ISNUMBER(SEARCH("Electric Vehicle",A5)),1,0) -> 0 | L5: Male
A6: bikes, car, Commercial vehicle | B6: 8 | D6: 45 | E6: 60 | F6: 10000 | G6: =IF(ISNUMBER(SEARCH("bike",A6)),1,0) -> 1 | H6: =IF(ISNUMBER(SEARCH("Scooty",A6)),1,0) -> 0 | I6: =IF(ISNUMBER(SEARCH("Car",A6)),1,0) -> 1 | J6: =IF(ISNUMBER(SEARCH("Commercial vehicle",A6)),1,0) -> 1 | K6: =IF(ISNUMBER(SEARCH("Electric Vehicle",A6)),1,0) -> 0 | L6: Male
A7: Scooty | C7: 10 | F7: 1200 | G7: =IF(ISNUMBER(SEARCH("bike",A7)),1,0) -> 0 | H7: =IF(ISNUMBER(SEARCH("Scooty",A7)),1,0) -> 1 | I7: =IF(ISNUMBER(SEARCH("Car",A7)),1,0) -> 0 | J7: =IF(ISNUMBER(SEARCH("Commercial vehicle",A7)),1,0) -> 0 | K7: =IF(ISNUMBER(SEARCH("Electric Vehicle",A7)),1,0) -> 0 | L7: Female
A8: bikes, car | B8: 20 | D8: 70 | F8: 1000 | G8: =IF(ISNUMBER(SEARCH("bike",A8)),1,0) -> 1 | H8: =IF(ISNUMBER(SEARCH("Scooty",A8)),1,0) -> 0 | I8: =IF(ISNUMBER(SEARCH("Car",A8)),1,0) -> 1 | J8: =IF(ISNUMBER(SEARCH("Commercial vehicle",A8)),1,0) -> 0 | K8: =IF(ISNUMBER(SEARCH("Electric Vehicle",A8)),1,0) -> 0 | L8: Female
A9: bikes | B9: 28 | F9: 3000 | G9: =IF(ISNUMBER(SEARCH("bike",A9)),1,0) -> 1 | H9: =IF(ISNUMBER(SEARCH("Scooty",A9)),1,0) -> 0 | I9: =IF(ISNUMBER(SEARCH("Car",A9)),1,0) -> 0 | J9: =IF(ISNUMBER(SEARCH("Commercial vehicle",A9)),1,0) -> 0 | K9: =IF(ISNUMBER(SEARCH("Electric Vehicle",A9)),1,0) -> 0 | L9: Male
A10: Scooty | C10: 12 | F10: 1500 | G10: =IF(ISNUMBER(SEARCH("bike",A10)),1,0) -> 0 | H10: =IF(ISNUMBER(SEARCH("Scooty",A10)),1,0) -> 1 | I10: =IF(ISNUMBER(SEARCH("Car",A10)),1,0) -> 0 | J10: =IF(ISNUMBER(SEARCH("Commercial vehicle",A10)),1,0) -> 0 | K10: =IF(ISNUMBER(SEARCH("Electric Vehicle",A10)),1,0) -> 0 | L10: Female
A11: car, Electric Vehicle | D11: 60 | F11: 9500 | G11: =IF(ISNUMBER(SEARCH("bike",A11)),1,0) -> 0 | H11: =IF(ISNUMBER(SEARCH("Scooty",A11)),1,0) -> 0 | I11: =IF(ISNUMBER(SEARCH("Car",A11)),1,0) -> 1 | J11: =IF(ISNUMBER(SEARCH("Commercial vehicle",A11)),1,0) -> 0 | K11: =IF(ISNUMBER(SEARCH("Electric Vehicle",A11)),1,0) -> 1 | L11: Male
A12: Scooty | C12: 8 | F12: 1500 | G12: =IF(ISNUMBER(SEARCH("bike",A12)),1,0) -> 0 | H12: =IF(ISNUMBER(SEARCH("Scooty",A12)),1,0) -> 1 | I12: =IF(ISNUMBER(SEARCH("Car",A12)),1,0) -> 0 | J12: =IF(ISNUMBER(SEARCH("Commercial vehicle",A12)),1,0) -> 0 | K12: =IF(ISNUMBER(SEARCH("Electric Vehicle",A12)),1,0) -> 0 | L12: Male
A13: bikes, Commercial vehicle | B13: 10 | E13: 70 | F13: 8000 | G13: =IF(ISNUMBER(SEARCH("bike",A13)),1,0) -> 1 | H13: =IF(ISNUMBER(SEARCH("Scooty",A13)),1,0) -> 0 | I13: =IF(ISNUMBER(SEARCH("Car",A13)),1,0) -> 0 | J13: =IF(ISNUMBER(SEARCH("Commercial vehicle",A13)),1,0) -> 1 | K13: =IF(ISNUMBER(SEARCH("Electric Vehicle",A13)),1,0) -> 0 | L13: Male
A14: bikes, car | B14: 12 | D14: 55 | F14: 6800 | G14: =IF(ISNUMBER(SEARCH("bike",A14)),1,0) -> 1 | H14: =IF(ISNUMBER(SEARCH("Scooty",A14)),1,0) -> 0 | I14: =IF(ISNUMBER(SEARCH("Car",A14)),1,0) -> 1 | J14: =IF(ISNUMBER(SEARCH("Commercial vehicle",A14)),1,0) -> 0 | K14: =IF(ISNUMBER(SEARCH("Electric Vehicle",A14)),1,0) -> 0 | L14: Female
A15: bikes, car | B15: 7 | D15: 70 | F15: 9000 | G15: =IF(ISNUMBER(SEARCH("bike",A15)),1,0) -> 1 | H15: =IF(ISNUMBER(SEARCH("Scooty",A15)),1,0) -> 0 | I15: =IF(ISNUMBER(SEARCH("Car",A15)),1,0) -> 1 | J15: =IF(ISNUMBER(SEARCH("Commercial vehicle",A15)),1,0) -> 0 | K15: =IF(ISNUMBER(SEARCH("Electric Vehicle",A15)),1,0) -> 0 | L15: Male
A16: bikes, Scooty, car | B16: 13 | C16: 9 | D16: 65 | F16: 9000 | G16: =IF(ISNUMBER(SEARCH("bike",A16)),1,0) -> 1 | H16: =IF(ISNUMBER(SEARCH("Scooty",A16)),1,0) -> 1 | I16: =IF(ISNUMBER(SEARCH("Car",A16)),1,0) -> 1 | J16: =IF(ISNUMBER(SEARCH("Commercial vehicle",A16)),1,0) -> 0 | K16: =IF(ISNUMBER(SEARCH("Electric Vehicle",A16)),1,0) -> 0 | L16: Male
A17: Scooty | C17: 7 | F17: 900 | G17: =IF(ISNUMBER(SEARCH("bike",A17)),1,0) -> 0 | H17: =IF(ISNUMBER(SEARCH("Scooty",A17)),1,0) -> 1 | I17: =IF(ISNUMBER(SEARCH("Car",A17)),1,0) -> 0 | J17: =IF(ISNUMBER(SEARCH("Commercial vehicle",A17)),1,0) -> 0 | K17: =IF(ISNUMBER(SEARCH("Electric Vehicle",A17)),1,0) -> 0 | L17: Female
A18: bikes, car | B18: 6 | D18: 25 | F18: 2000 | G18: =IF(ISNUMBER(SEARCH("bike",A18)),1,0) -> 1 | H18: =IF(ISNUMBER(SEARCH("Scooty",A18)),1,0) -> 0 | I18: =IF(ISNUMBER(SEARCH("Car",A18)),1,0) -> 1 | J18: =IF(ISNUMBER(SEARCH("Commercial vehicle",A18)),1,0) -> 0 | K18: =IF(ISNUMBER(SEARCH("Electric Vehicle",A18)),1,0) -> 0 | L18: Male
A19: bikes | B19: 18 | F19: 2300 | G19: =IF(ISNUMBER(SEARCH("bike",A19)),1,0) -> 1 | H19: =IF(ISNUMBER(SEARCH("Scooty",A19)),1,0) -> 0 | I19: =IF(ISNUMBER(SEARCH("Car",A19)),1,0) -> 0 | J19: =IF(ISNUMBER(SEARCH("Commercial vehicle",A19)),1,0) -> 0 | K19: =IF(ISNUMBER(SEARCH("Electric Vehicle",A19)),1,0) -> 0 | L19: Male
A20: Scooty | C20: 10 | F20: 1200 | G20: =IF(ISNUMBER(SEARCH("bike",A20)),1,0) -> 0 | H20: =IF(ISNUMBER(SEARCH("Scooty",A20)),1,0) -> 1 | I20: =IF(ISNUMBER(SEARCH("Car",A20)),1,0) -> 0 | J20: =IF(ISNUMBER(SEARCH("Commercial vehicle",A20)),1,0) -> 0 | K20: =IF(ISNUMBER(SEARCH("Electric Vehicle",A20)),1,0) -> 0 | L20: Female
A21: bikes, Commercial vehicle | B21: 10 | E21: 80 | F21: 11100 | G21: =IF(ISNUMBER(SEARCH("bike",A21)),1,0) -> 1 | H21: =IF(ISNUMBER(SEARCH("Scooty",A21)),1,0) -> 0 | I21: =IF(ISNUMBER(SEARCH("Car",A21)),1,0) -> 0 | J21: =IF(ISNUMBER(SEARCH("Commercial vehicle",A21)),1,0) -> 1 | K21: =IF(ISNUMBER(SEARCH("Electric Vehicle",A21)),1,0) -> 0 | L21: Male
A22: car | D22: 50 | F22: 6000 | G22: =IF(ISNUMBER(SEARCH("bike",A22)),1,0) -> 0 | H22: =IF(ISNUMBER(SEARCH("Scooty",A22)),1,0) -> 0 | I22: =IF(ISNUMBER(SEARCH("Car",A22)),1,0) -> 1 | J22: =IF(ISNUMBER(SEARCH("Commercial vehicle",A22)),1,0) -> 0 | K22: =IF(ISNUMBER(SEARCH("Electric Vehicle",A22)),1,0) -> 0 | L22: Female
A23: bikes, car, Electric Vehicle | B23: 6 | D23: 55 | F23: 8800 | G23: =IF(ISNUMBER(SEARCH("bike",A23)),1,0) -> 1 | H23: =IF(ISNUMBER(SEARCH("Scooty",A23)),1,0) -> 0 | I23: =IF(ISNUMBER(SEARCH("Car",A23)),1,0) -> 1 | J23: =IF(ISNUMBER(SEARCH("Commercial vehicle",A23)),1,0) -> 0 | K23: =IF(ISNUMBER(SEARCH("Electric Vehicle",A23)),1,0) -> 1 | L23: Male
A24: bikes | B24: 24 | F24: 2700 | G24: =IF(ISNUMBER(SEARCH("bike",A24)),1,0) -> 1 | H24: =IF(ISNUMBER(SEARCH("Scooty",A24)),1,0) -> 0 | I24: =IF(ISNUMBER(SEARCH("Car",A24)),1,0) -> 0 | J24: =IF(ISNUMBER(SEARCH("Commercial vehicle",A24)),1,0) -> 0 | K24: =IF(ISNUMBER(SEARCH("Electric Vehicle",A24)),1,0) -> 0 | L24: Male
A25: bikes, Scooty | B25: 9 | C25: 8 | F25: 3000 | G25: =IF(ISNUMBER(SEARCH("bike",A25)),1,0) -> 1 | H25: =IF(ISNUMBER(SEARCH("Scooty",A25)),1,0) -> 1 | I25: =IF(ISNUMBER(SEARCH("Car",A25)),1,0) -> 0 | J25: =IF(ISNUMBER(SEARCH("Commercial vehicle",A25)),1,0) -> 0 | K25: =IF(ISNUMBER(SEARCH("Electric Vehicle",A25)),1,0) -> 0 | L25: Female
A26: Scooty, car | C26: 9 | D26: 40 | F26: 5200 | G26: =IF(ISNUMBER(SEARCH("bike",A26)),1,0) -> 0 | H26: =IF(ISNUMBER(SEARCH("Scooty",A26)),1,0) -> 1 | I26: =IF(ISNUMBER(SEARCH("Car",A26)),1,0) -> 1 | J26: =IF(ISNUMBER(SEARCH("Commercial vehicle",A26)),1,0) -> 0 | K26: =IF(ISNUMBER(SEARCH("Electric Vehicle",A26)),1,0) -> 0 | L26: Female
A27: bikes, car | B27: 7 | D27: 70 | F27: 9700 | G27: =IF(ISNUMBER(SEARCH("bike",A27)),1,0) -> 1 | H27: =IF(ISNUMBER(SEARCH("Scooty",A27)),1,0) -> 0 | I27: =IF(ISNUMBER(SEARCH("Car",A27)),1,0) -> 1 | J27: =IF(ISNUMBER(SEARCH("Commercial vehicle",A27)),1,0) -> 0 | K27: =IF(ISNUMBER(SEARCH("Electric Vehicle",A27)),1,0) -> 0 | L27: Male
A28: bikes, Commercial vehicle | B28: 12 | E28: 65 | F28: 8200 | G28: =IF(ISNUMBER(SEARCH("bike",A28)),1,0) -> 1 | H28: =IF(ISNUMBER(SEARCH("Scooty",A28)),1,0) -> 0 | I28: =IF(ISNUMBER(SEARCH("Car",A28)),1,0) -> 0 | J28: =IF(ISNUMBER(SEARCH("Commercial vehicle",A28)),1,0) -> 1 | K28: =IF(ISNUMBER(SEARCH("Electric Vehicle",A28)),1,0) -> 0 | L28: Female
A29: bikes | B29: 20 | F29: 2400 | G29: =IF(ISNUMBER(SEARCH("bike",A29)),1,0) -> 1 | H29: =IF(ISNUMBER(SEARCH("Scooty",A29)),1,0) -> 0 | I29: =IF(ISNUMBER(SEARCH("Car",A29)),1,0) -> 0 | J29: =IF(ISNUMBER(SEARCH("Commercial vehicle",A29)),1,0) -> 0 | K29: =IF(ISNUMBER(SEARCH("Electric Vehicle",A29)),1,0) -> 0 | L29: Male
A30: bikes | B30: 26 | F30: 2900 | G30: =IF(ISNUMBER(SEARCH("bike",A30)),1,0) -> 1 | H30: =IF(ISNUMBER(SEARCH("Scooty",A30)),1,0) -> 0 | I30: =IF(ISNUMBER(SEARCH("Car",A30)),1,0) -> 0 | J30: =IF(ISNUMBER(SEARCH("Commercial vehicle",A30)),1,0) -> 0 | K30: =IF(ISNUMBER(SEARCH("Electric Vehicle",A30)),1,0) -> 0 | L30: Male
A31: bikes, Scooty, car | B31: 16 | C31: 6 | D31: 60 | F31: 9500 | G31: =IF(ISNUMBER(SEARCH("bike",A31)),1,0) -> 1 | H31: =IF(ISNUMBER(SEARCH("Scooty",A31)),1,0) -> 1 | I31: =IF(ISNUMBER(SEARCH("Car",A31)),1,0) -> 1 | J31: =IF(ISNUMBER(SEARCH("Commercial vehicle",A31)),1,0) -> 0 | K31: =IF(ISNUMBER(SEARCH("Electric Vehicle",A31)),1,0) -> 0 | L31: Male
A32: car | D32: 45 | F32: 5200 | G32: =IF(ISNUMBER(SEARCH("bike",A32)),1,0) -> 0 | H32: =IF(ISNUMBER(SEARCH("Scooty",A32)),1,0) -> 0 | I32: =IF(ISNUMBER(SEARCH("Car",A32)),1,0) -> 1 | J32: =IF(ISNUMBER(SEARCH("Commercial vehicle",A32)),1,0) -> 0 | K32: =IF(ISNUMBER(SEARCH("Electric Vehicle",A32)),1,0) -> 0 | L32: Female
A33: bikes, car | B33: 7 | D33: 65 | F33: 8500 | G33: =IF(ISNUMBER(SEARCH("bike",A33)),1,0) -> 1 | H33: =IF(ISNUMBER(SEARCH("Scooty",A33)),1,0) -> 0 | I33: =IF(ISNUMBER(SEARCH("Car",A33)),1,0) -> 1 | J33: =IF(ISNUMBER(SEARCH("Commercial vehicle",A33)),1,0) -> 0 | K33: =IF(ISNUMBER(SEARCH("Electric Vehicle",A33)),1,0) -> 0 | L33: Male
